Workbook

Sheet README
A1: FHWS student transport to clinical sites: standardised workbook (AY2024 + AY2025)
A3: Purpose | B3: Standard format for FHWS transport requests so AY2024 and AY2025 can be analysed together in Excel and later loaded into Power BI.
A4: Sources | B4: FHWS__Transport_requests_AY2024_19_Aug_2024.xlsx (92 request lines) and FHWS_Transport_requirements_to_clinical_sites_AY2025.docx (requirements only).
A5: Fact_Trips | B5: One row per request line (a route on a block of dates). AY2024: 92 request lines with TSQT, units and cost. AY2025: 96 requirement lines, one per site, without TSQT, dates or cost (Record_Type tells them apart). Filter on Record_Type before summing trips or cost.
A6: Bridge_Trip_Site | B6: Links each Fact_Trips line to the sites on its route (a route can visit several sites).
A7: Bridge_Trip_Date | B7: AY2024 trip days parsed from the date text, for date-level analysis (clashes by site and day). Reconciled_To_Units = No means the dates do not match units booked; see Data Issues.
A8: Dim_Department / Dim_Vehicle / Dim_Site / Dim_Date | B8: Lookup tables. Keys: Dept_ID, Vehicle_ID, Site_ID, Date.
A9: Data Issues | B9: Hand-over log: every problem found, how it was treated here and what needs confirming.
A10: Schedule Organiser | B10: Dummy planning template with drop-downs and a flag when two departments book the same site on the same day.
A11: Reconciliation | B11: Total_Cost for AY2024 equals the 1,620,700 total in the source file (checked: Fact_Trips total row).
A12: Key assumptions | B12: Units is the smaller of the cost-per-unit/units pair; 'number of students' read as vehicle capacity; blank TSQT/department filled down; SA public holidays as in Dim_Date; 2026 data not included. Details in Data Issues.
A14: Assumptions: AY2025 costs
A15: Assumed cost per trip, AY2025 site not served by the department in AY2024 | B15: 3600
A16: Rule | B16: AY2025 lines take the AY2024 cost per trip of the same department's trip to the same site. If that AY2024 trip visited several sites, its cost is divided across them. Sites the department did not serve in AY2024 use the cell above. Trips (units) for AY2025 are still blank, so AY2025 Total_Cost stays blank.

Sheet Fact_Trips
A1: Trip_ID | B1: AY | C1: Record_Type | D1: Dept_ID | E1: Dept_Code | F1: Vehicle_ID | G1: TSQT_Number | H1: TSQT_Source | I1: Start_Date | J1: End_Date | K1: Dates_As_Captured | L1: Parsed_Trip_Days | M1: Trips | N1: Date_Check | O1: Depart_Time | P1: Return_Time | Q1: Shift_Type | R1: Times_As_Captured | S1: Students_As_Captured | T1: Direction | U1: Route_As_Captured | V1: Sites_In_Route | W1: Cost_Per_Trip | X1: Total_Cost | Y1: Source_Row_AY2024 | Z1: Cost_Basis | AA1: Cost_Source_Trip_IDs | AB1: Cost_Note
A2: T2024-001 | B2: AY2024 | C2: Request (AY2024) | D2: 1 | E2: =INDEX(Dim_Department!$B$2:$B$5,MATCH(D2,Dim_Department!$A$2:$A$5,0)) -> Nursing | F2: V03 | G2: TSQT0002930 | H2: Stated | I2: 45383 | J2: 45383 | K2: 01 April 2024 | L2: 1 | M2: 1 | N2: Single date | Q2: One way / collection only | R2: pick up 12h00 one way | S2: 10 | T2: One way from South Point, Belhar | U2: South Point, Belhar to Worcester hospital (Drop off | V2: =COUNTIF(Bridge_Trip_Site!$A$2:$A$2000,A2) -> 1 | W2: 3600 | X2: =IF(AND(ISNUMBER(M2),ISNUMBER(W2)),M2*W2,"") -> 3600 | Y2: 3 | Z2: Quoted (TSQT)
A3: T2024-002 | B3: AY2024 | C3: Request (AY2024) | D3: 1 | E3: =INDEX(Dim_Department!$B$2:$B$5,MATCH(D3,Dim_Department!$A$2:$A$5,0)) -> Nursing | F3: V03 | G3: TSQT0002930 | H3: Stated | I3: 45423 | J3: 45423 | K3: 11 May 2024 | L3: 1 | M3: 1 | N3: Single date | Q3: One way / collection only | R3: Collect at 12h00 | S3: 10 | T3: One way to South Point, Belhar (collection) | U3: Worester hospital to South Point, Belhar (Collect | V3: =COUNTIF(Bridge_Trip_Site!$A$2:$A$2000,A3) -> 1 | W3: 3600 | X3: =IF(AND(ISNUMBER(M3),ISNUMBER(W3)),M3*W3,"") -> 3600 | Y3: 4 | Z3: Quoted (TSQT)
A4: T2024-003 | B4: AY2024 | C4: Request (AY2024) | D4: 1 | E4: =INDEX(Dim_Department!$B$2:$B$5,MATCH(D4,Dim_Department!$A$2:$A$5,0)) -> Nursing | F4: V04 | G4: TSQT0002931 | H4: Stated | I4: 45384 | J4: 45394 | K4: 02-12 April 2024 | L4: 9 | M4: 9 | N4: Matches units (9) | O4: 0.22916667 | P4: 0.8125 | Q4: Day | R4: 05h30 return 19h30 | S4: 13 | T4: Return from Bellville Campus | U4: Bellville Campus to Tygerberg and Karl Bremmer hospitals and return | V4: =COUNTIF(Bridge_Trip_Site!$A$2:$A$2000,A4) -> 2 | W4: 980 | X4: =IF(AND(ISNUMBER(M4),ISNUMBER(W4)),M4*W4,"") -> 8820 | Y4: 5 | Z4: Quoted (TSQT)
A5: T2024-004 | B5: AY2024 | C5: Request (AY2024) | D5: 1 | E5: =INDEX(Dim_Department!$B$2:$B$5,MATCH(D5,Dim_Department!$A$2:$A$5,0)) -> Nursing | F5: V04 | G5: TSQT0002931 | H5: Stated | I5: 45384 | J5: 45422 | K5: 02-30 April to 10 May 2024 | L5: 28 | M5: 28 | N5: Matches units (28) | O5: 0.22916667 | P5: 0.6875 | Q5: Day | R5: 05h30 return 16h30 | S5: 13 | T5: Return from Bellville Campus | U5: Bellville Campus to New Somerset hospital and return | V5: =COUNTIF(Bridge_Trip_Site!$A$2:$A$2000,A5) -> 1 | W5: 980 | X5: =IF(AND(ISNUMBER(M5),ISNUMBER(W5)),M5*W5,"") -> 27440 | Y5: 6 | Z5: Quoted (TSQT)
A6: T2024-005 | B6: AY2024 | C6: Request (AY2024) | D6: 1 | E6: =INDEX(Dim_Department!$B$2:$B$5,MATCH(D6,Dim_Department!$A$2:$A$5,0)) -> Nursing | F6: V04 | G6: TSQT0002955 | H6: Stated | I6: 45384 | J6: 45422 | K6: 02 - 30 April 2024 to 10 May 2024 | L6: 28 | M6: 28 | N6: Matches units (28) | O6: 0.22916667 | P6: 0.6875 | Q6: Day | R6: 05h30 return 16h30 | S6: 13 | T6: Return from Bellville Campus | U6: Bellville Campus to Mitchell's Plain, Michael M, Site B, Kuyasa, Nolungile, Rocklands, Lentegeur clinics and return | V6: =COUNTIF(Bridge_Trip_Site!$A$2:$A$2000,A6) -> 7 | W6: 1600 | X6: =IF(AND(ISNUMBER(M6),ISNUMBER(W6)),M6*W6,"") -> 44800 | Y6: 7 | Z6: Quoted (TSQT)
A7: T2024-006 | B7: AY2024 | C7: Request (AY2024) | D7: 1 | E7: =INDEX(Dim_Department!$B$2:$B$5,MATCH(D7,Dim_Department!$A$2:$A$5,0)) -> Nursing | F7: V04 | G7: TSQT0002955 | H7: Stated | I7: 45384 | J7: 45408 | K7: 02-12, 15-26 April 2024 | L7: 19 | M7: 19 | N7: Matches units (19) | O7: 0.22916667 | P7: 0.6875 | Q7: Day | R7: 05h30 return 16h30 | S7: 13 | T7: Return from Bellville Campus | U7: Bellville Campus to Lotus River, Retreat, Lady Michaelis, D6 clinic and retur | V7: =COUNTIF(Bridge_Trip_Site!$A$2:$A$2000,A7) -> 4 | W7: 1600 | X7: =IF(AND(ISNUMBER(M7),ISNUMBER(W7)),M7*W7,"") -> 30400 | Y7: 8 | Z7: Quoted (TSQT)
A8: T2024-007 | B8: AY2024 | C8: Request (AY2024) | D8: 1 | E8: =INDEX(Dim_Department!$B$2:$B$5,MATCH(D8,Dim_Department!$A$2:$A$5,0)) -> Nursing | F8: V04 | G8: TSQT0002955 | H8: Stated | I8: 45384 | J8: 45422 | K8: 02-12, 29 & 30 April to 10 May 2024 | L8: 18 | M8: 18 | N8: Matches units (18) | O8: 0.22916667 | P8: 0.6875 | Q8: Day | R8: 05h30 return 16h30 | S8: 13 | T8: Return from Bellville Campus | U8: Bellville Campus to Vanguard, Langa, Lansdowne, Nyanga, Gugulethu and return | V8: =COUNTIF(Bridge_Trip_Site!$A$2:$A$2000,A8) -> 5 | W8: 1200 | X8: =IF(AND(ISNUMBER(M8),ISNUMBER(W8)),M8*W8,"") -> 21600 | Y8: 9 | Z8: Quoted (TSQT)
A9: T2024-008 | B9: AY2024 | C9: Request (AY2024) | D9: 1 | E9: =INDEX(Dim_Department!$B$2:$B$5,MATCH(D9,Dim_Department!$A$2:$A$5,0)) -> Nursing | F9: V04 | G9: TSQT0002956 | H9: Stated | I9: 45384 | J9: 45422 | K9: 02 - 30 April 2024 to 10 May 2024 | L9: 28 | M9: 28 | N9: Matches units (28) | O9: 0.22916667 | P9: 0.6875 | Q9: Day | R9: 05h30 return 16h30 | S9: 13 | T9: Return from Bellville Campus | U9: Bellville Campus to Reed Street, Parow, Dirkie Uys, Ruyterwacht, Ravensmead, Elsie | V9: =COUNTIF(Bridge_Trip_Site!$A$2:$A$2000,A9) -> 5 | W9: 980 | X9: =IF(AND(ISNUMBER(M9),ISNUMBER(W9)),M9*W9,"") -> 27440 | Y9: 10 | Z9: Quoted (TSQT)
A10: T2024-009 | B10: AY2024 | C10: Request (AY2024) | D10: 1 | E10: =INDEX(Dim_Department!$B$2:$B$5,MATCH(D10,Dim_Department!$A$2:$A$5,0)) -> Nursing | F10: V04 | G10: TSQT0002956 | H10: Stated | I10: 45384 | J10: 45422 | K10: 02 - 30 April 2024 to 10 May 2024 | L10: 28 | M10: 28 | N10: Matches units (28) | O10: 0.22916667 | P10: 0.6875 | Q10: Day | R10: 05h30 return 16h30 | S10: 13 | T10: Return from Bellville Campus | U10: Bellville Campus Campus to St Vincent, Symphony, Kasselsvlei, Scottsdene and return | V10: =COUNTIF(Bridge_Trip_Site!$A$2:$A$2000,A10) -> 4 | W10: 1400 | X10: =IF(AND(ISNUMBER(M10),ISNUMBER(W10)),M10*W10,"") -> 39200 | Y10: 11 | Z10: Quoted (TSQT)
A11: T2024-010 | B11: AY2024 | C11: Request (AY2024) | D11: 1 | E11: =INDEX(Dim_Department!$B$2:$B$5,MATCH(D11,Dim_Department!$A$2:$A$5,0)) -> Nursing | F11: V04 | G11: TSQT0002956 | H11: Stated | I11: 45384 | J11: 45422 | K11: 02 - 30 April 2024 to 10 May 2024 | L11: 28 | M11: 9 | N11: MISMATCH: 28 dates parsed vs 9 units booked | O11: 0.22916667 | P11: 0.6875 | Q11: Day | R11: 05h30 return 16h30 | S11: 13 | T11: Return from Bellville Campus | U11: Bellville Campus to Strand, Macassar & Gustrow and return | V11: =COUNTIF(Bridge_Trip_Site!$A$2:$A$2000,A11) -> 3 | W11: 2600 | X11: =IF(AND(ISNUMBER(M11),ISNUMBER(W11)),M11*W11,"") -> 23400 | Y11: 12 | Z11: Quoted (TSQT)
A12: T2024-011 | B12: AY2024 | C12: Request (AY2024) | D12: 1 | E12: =INDEX(Dim_Department!$B$2:$B$5,MATCH(D12,Dim_Department!$A$2:$A$5,0)) -> Nursing | F12: V01 | G12: TSQT0002959 | H12: Stated | I12: 45376 | J12: 45379 | K12: 25 - 28 March 2024 | L12: 4 | M12: 4 | N12: Matches units (4) | Q12: One way / collection only | R12: 16h30 | S12: 4 | T12: One way to Bellville Campus | U12: Retreat, Gugulethu, Vanguard to drop off at Bellville Campus | V12: =COUNTIF(Bridge_Trip_Site!$A$2:$A$2000,A12) -> 3 | W12: 800 | X12: =IF(AND(ISNUMBER(M12),ISNUMBER(W12)),M12*W12,"") -> 3200 | Y12: 13 | Z12: Quoted (TSQT)
A13: T2024-012 | B13: AY2024 | C13: Request (AY2024) | D13: 1 | E13: =INDEX(Dim_Department!$B$2:$B$5,MATCH(D13,Dim_Department!$A$2:$A$5,0)) -> Nursing | F13: V01 | G13: TSQT0002959 | H13: Stated | I13: 45376 | J13: 45379 | K13: 25 - 28 March 2024 | L13: 4 | M13: 4 | N13: Matches units (4) | Q13: One way / collection only | R13: 16h30 | S13: 4 | T13: One way to Bellville Campus | U13: Macassar, Michael M, Site B, Mitchell's Plain drop off at Bellville Campus | V13: =COUNTIF(Bridge_Trip_Site!$A$2:$A$2000,A13) -> 4 | W13: 800 | X13: =IF(AND(ISNUMBER(M13),ISNUMBER(W13)),M13*W13,"") -> 3200 | Y13: 14 | Z13: Quoted (TSQT)
A14: T2024-013 | B14: AY2024 | C14: Request (AY2024) | D14: 2 | E14: =INDEX(Dim_Department!$B$2:$B$5,MATCH(D14,Dim_Department!$A$2:$A$5,0)) -> DEMS | F14: V02 | G14: TSQT0002978 | H14: Stated | I14: 45405 | J14: 45412 | K14: 23 &30 April 2024 | L14: 2 | M14: 2 | N14: Matches units (2) | Q14: Day and night shifts | R14: 06h00 & 18h00 return 18h00 & 06h00 | S14: 7 | T14: Return from Bellville Campus | U14: Bellville Campus to Eersteriver hospital and back | V14: =COUNTIF(Bridge_Trip_Site!$A$2:$A$2000,A14) -> 1 | W14: 850 | X14: =IF(AND(ISNUMBER(M14),ISNUMBER(W14)),M14*W14,"") -> 1700 | Y14: 15 | Z14: Quoted (TSQT)
A15: T2024-014 | B15: AY2024 | C15: Request (AY2024) | D15: 2 | E15: =INDEX(Dim_Department!$B$2:$B$5,MATCH(D15,Dim_Department!$A$2:$A$5,0)) -> DEMS | F15: V02 | G15: TSQT0002978 | H15: Stated | I15: 45394 | J15: 45464 | K15: 12, 13, 14, 16, 18, 19, 20, 21, 26, 27, 28 April & 03, 04, 05, 11, 17, 18, 19, 24, 25, 26, 31 May & 01, 02, 08, 09, 14, 15, 16, 21 June 2024 | L15: 30 | M15: 30 | N15: Matches units (30) | Q15: Day and night shifts | R15: 06h00 & 18h00 return 18h00 & 06h00 | S15: 7 | T15: Return from Bellville Campus | U15: Bellville Campus to Khayelitsha hospital and back | V15: =COUNTIF(Bridge_Trip_Site!$A$2:$A$2000,A15) -> 1 | W15: 850 | X15: =IF(AND(ISNUMBER(M15),ISNUMBER(W15)),M15*W15,"") -> 25500 | Y15: 16 | Z15: Quoted (TSQT)
A16: T2024-015 | B16: AY2024 | C16: Request (AY2024) | D16: 2 | E16: =INDEX(Dim_Department!$B$2:$B$5,MATCH(D16,Dim_Department!$A$2:$A$5,0)) -> DEMS | F16: V02 | G16: TSQT0002978 | H16: Stated | I16: 45395 | J16: 45458 | K16: 13, 14, 16, 18, 19, 20, 23, 30 April & 02, 04, 07, 11, 14, 18, 25 May & 15 June 2024 | L16: 16 | M16: 16 | N16: Matches units (16) | Q16: Day and night shifts | R16: 06h00 & 18h00 return 18h00 & 06h00 | S16: 7 | T16: Return from Bellville Campus | U16: Bellville Campus to Groote Schuur hospital and back | V16: =COUNTIF(Bridge_Trip_Site!$A$2:$A$2000,A16) -> 1 | W16: 850 | X16: =IF(AND(ISNUMBER(M16),ISNUMBER(W16)),M16*W16,"") -> 13600 | Y16: 17 | Z16: Quoted (TSQT)
A17: T2024-016 | B17: AY2024 | C17: Request (AY2024) | D17: 2 | E17: =INDEX(Dim_Department!$B$2:$B$5,MATCH(D17,Dim_Department!$A$2:$A$5,0)) -> DEMS | F17: V02 | G17: TSQT0002978 | H17: Stated | I17: 45394 | J17: 45458 | K17: 12, 13, 14, 16, 18, 20, 23, 25, 26, 27, 30 April & 01, 04, 05, 09 ,10, 11, 14, 18, 19, 25, 26 May & 01, 02, 09, 15 June 2024 | L17: 26 | M17: 26 | N17: Matches units (26) | Q17: Day and night shifts | R17: 06h00 & 18h00 return 18h00 & 06h00 | S17: 7 | T17: Return from Bellville Campus | U17: Bellville Campus to Tygerberg & Karl Bremmer hospitals and back | V17: =COUNTIF(Bridge_Trip_Site!$A$2:$A$2000,A17) -> 2 | W17: 750 | X17: =IF(AND(ISNUMBER(M17),ISNUMBER(W17)),M17*W17,"") -> 19500 | Y17: 18 | Z17: Quoted (TSQT)
A18: T2024-017 | B18: AY2024 | C18: Request (AY2024) | D18: 2 | E18: =INDEX(Dim_Department!$B$2:$B$5,MATCH(D18,Dim_Department!$A$2:$A$5,0)) -> DEMS | F18: V02 | G18: TSQT0003071 | H18: Stated | I18: 45395 | J18: 45472 | K18: 13, 27 April, 03, 11, 18, 25, 26 May, 02, 15 & 29 June 2024 | L18: 10 | M18: 10 | N18: Matches units (10) | Q18: Day and night shifts | R18: 06h00 & 18h00 return 18h00 & 06h00 | S18: 7 | T18: Return from Bellville Campus | U18: Bellville Campus to Mitchell's Plain hospital and back | V18: =COUNTIF(Bridge_Trip_Site!$A$2:$A$2000,A18) -> 1 | W18: 850 | X18: =IF(AND(ISNUMBER(M18),ISNUMBER(W18)),M18*W18,"") -> 8500 | Y18: 19 | Z18: Quoted (TSQT)
A19: T2024-018 | B19: AY2024 | C19: Request (AY2024) | D19: 2 | E19: =INDEX(Dim_Department!$B$2:$B$5,MATCH(D19,Dim_Department!$A$2:$A$5,0)) -> DEMS | F19: V02 | G19: TSQT0003071 | H19: Stated | I19: 45394 | J19: 45459 | K19: 12, 14, 21, 26, 27 April, 11, 18, 25 May & 16 June 2024 | L19: 9 | M19: 9 | N19: Matches units (9) | Q19: Day and night shifts | R19: 06h00 & 18h00 return 18h00 & 06h00 | S19: 7 | T19: Return from Bellville Campus | U19: Bellville Campus to Pinelands EMS Base and back | V19: =COUNTIF(Bridge_Trip_Site!$A$2:$A$2000,A19) -> 1 | W19: 850 | X19: =IF(AND(ISNUMBER(M19),ISNUMBER(W19)),M19*W19,"") -> 7650 | Y19: 20 | Z19: Quoted (TSQT)
A20: T2024-019 | B20: AY2024 | C20: Request (AY2024) | D20: 2 | E20: =INDEX(Dim_Department!$B$2:$B$5,MATCH(D20,Dim_Department!$A$2:$A$5,0)) -> DEMS | F20: V02 | G20: TSQT0003071 | H20: Stated | I20: 45415 | J20: 45451 | K20: 03, 04, 11, 24, 25 May, 08 June 2024 | L20: 6 | M20: 6 | N20: Matches units (6) | Q20: Day and night shifts | R20: 06h00 & 18h00 return 18h00 & 06h00 | S20: 7 | T20: Return from Bellville Campus | U20: Bellville Campus to Gugulethu hospital and back | V20: =COUNTIF(Bridge_Trip_Site!$A$2:$A$2000,A20) -> 1 | W20: 850 | X20: =IF(AND(ISNUMBER(M20),ISNUMBER(W20)),M20*W20,"") -> 5100 | Y20: 21 | Z20: Quoted (TSQT)
A21: T2024-020 | B21: AY2024 | C21: Request (AY2024) | D21: 3 | E21: =INDEX(Dim_Department!$B$2:$B$5,MATCH(D21,Dim_Department!$A$2:$A$5,0)) -> MITS | F21: V02 | G21: TSQT0003107 | H21: Stated | I21: 45417 | J21: 45460 | K21: 05, 11, 18, 19, May & 08, 09, 15, 17 June 2024 | L21: 8 | M21: 8 | N21: Matches units (8) | O21: 0.29166667 | P21: 0.66666667 | Q21: Day | R21: 07h00 return 16h00 | S21: 7 | T21: Return from Bellville Campus | U21: Bellville campus to Groote Schuur hospital and back | V21: =COUNTIF(Bridge_Trip_Site!$A$2:$A$2000,A21) -> 1 | W21: 850 | X21: =IF(AND(ISNUMBER(M21),ISNUMBER(W21)),M21*W21,"") -> 6800 | Y21: 22 | Z21: Quoted (TSQT)
A22: T2024-021 | B22: AY2024 | C22: Request (AY2024) | D22: 3 | E22: =INDEX(Dim_Department!$B$2:$B$5,MATCH(D22,Dim_Department!$A$2:$A$5,0)) -> MITS | F22: V02 | G22: TSQT0003107 | H22: Stated | I22: 45418 | J22: 45462 | K22: 06, 07, 09 May & 09, 10, 12, 17, 19 June 2024 | L22: 8 | M22: 9 | N22: MISMATCH: 8 dates parsed vs 9 units booked | O22: 0.75 | P22: 0.29166667 | Q22: Night duty | R22: 18h00 return 07h00 | S22: 7 | T22: Return from Bellville Campus | U22: Bellville campus to Groote Schuur hospital and back | V22: =COUNTIF(Bridge_Trip_Site!$A$2:$A$2000,A22) -> 1 | W22: 850 | X22: =IF(AND(ISNUMBER(M22),ISNUMBER(W22)),M22*W22,"") -> 7650 | Y22: 23 | Z22: Quoted (TSQT)
A23: T2024-022 | B23: AY2024 | C23: Request (AY2024) | D23: 3 | E23: =INDEX(Dim_Department!$B$2:$B$5,MATCH(D23,Dim_Department!$A$2:$A$5,0)) -> MITS | F23: V02 | G23: TSQT0003107 | H23: Stated | I23: 45418 | J23: 45464 | K23: 06, 07, 08, 09, 10, 20, 21, 22, 23 May & 10, 11, 12, 13, 14, 18, 19, 20, 21 June 202 | L23: 18 | M23: 18 | N23: Matches units (18) | O23: 0.25 | P23: 0.66666667 | Q23: Day | R23: 06h00 return16h00 | S23: 7 | T23: Return from Bellville Campus | U23: Bellville campus to New Somerset, Mowbray and Red Cross hospitals and back | V23: =COUNTIF(Bridge_Trip_Site!$A$2:$A$2000,A23) -> 3 | W23: 1200 | X23: =IF(AND(ISNUMBER(M23),ISNUMBER(W23)),M23*W23,"") -> 21600 | Y23: 24 | Z23: Quoted (TSQT)
A24: T2024-023 | B24: AY2024 | C24: Request (AY2024) | D24: 3 | E24: =INDEX(Dim_Department!$B$2:$B$5,MATCH(D24,Dim_Department!$A$2:$A$5,0)) -> MITS | F24: V02 | G24: TSQT0003107 | H24: Stated | I24: 45425 | J24: 45428 | K24: 13, 14, 16 May 2024 | L24: 3 | M24: 3 | N24: Matches units (3) | O24: 0.75 | P24: 0.29166667 | Q24: Night duty | R24: 18h00 return 07h00 | S24: 7 | T24: Return from Bellville Campus | U24: -Bellville Campus to New Somerset hospital and return | V24: =COUNTIF(Bridge_Trip_Site!$A$2:$A$2000,A24) -> 1 | W24: 850 | X24: =IF(AND(ISNUMBER(M24),ISNUMBER(W24)),M24*W24,"") -> 2550 | Y24: 25 | Z24: Quoted (TSQT)
A25: T2024-024 | B25: AY2024 | C25: Request (AY2024) | D25: 3 | E25: =INDEX(Dim_Department!$B$2:$B$5,MATCH(D25,Dim_Department!$A$2:$A$5,0)) -> MITS | F25: V02 | G25: TSQT0003107 | H25: Stated | I25: 45418 | J25: 45464 | K25: 06, 07, 08, 09, 10, 20, 21, 22, 23 May & 10, 11, 12, 13, 14, 18, 19, 20, 21 June 202 | L25: 18 | M25: 18 | N25: Matches units (18) | O25: 0.27083333 | P25: 0.66666667 | Q25: Day | R25: 06h30 return 16h00 | S25: 7 | T25: Return from Bellville Campus | U25: Bellville campus to Khayelitsha District hospital and bac | V25: =COUNTIF(Bridge_Trip_Site!$A$2:$A$2000,A25) -> 1 | W25: 1200 | X25: =IF(AND(ISNUMBER(M25),ISNUMBER(W25)),M25*W25,"") -> 21600 | Y25: 26 | Z25: Quoted (TSQT)
A26: T2024-025 | B26: AY2024 | C26: Request (AY2024) | D26: 3 | E26: =INDEX(Dim_Department!$B$2:$B$5,MATCH(D26,Dim_Department!$A$2:$A$5,0)) -> MITS | F26: V02 | G26: TSQT0003107 | H26: Stated | I26: 45432 | J26: 45464 | K26: 20, 21, 22, 23 May & 18, 19, 20, 21 June 2024 | L26: 8 | M26: 8 | N26: Matches units (8) | O26: 0.27083333 | P26: 0.66666667 | Q26: Day | R26: 06h30 return 16h00 | S26: 7 | T26: Return from Bellville Campus | U26: Bellville campus to Kraaifontein CHC and back | V26: =COUNTIF(Bridge_Trip_Site!$A$2:$A$2000,A26) -> 1 | W26: 1200 | X26: =IF(AND(ISNUMBER(M26),ISNUMBER(W26)),M26*W26,"") -> 9600 | Y26: 27 | Z26: Quoted (TSQT)
A27: T2024-026 | B27: AY2024 | C27: Request (AY2024) | D27: 3 | E27: =INDEX(Dim_Department!$B$2:$B$5,MATCH(D27,Dim_Department!$A$2:$A$5,0)) -> MITS | F27: V02 | G27: TSQT0003107 | H27: Stated | I27: 45418 | J27: 45464 | K27: 06, 07, 08, 09, 10, 13, 14, 15, 16, 17, 20, 21, 22, 23 May & 18, 19, 20, 21 June 2024 | L27: 18 | M27: 18 | N27: Matches units (18) | O27: 0.25 | P27: 0.66666667 | Q27: Day | R27: 06h00 return 16h00 | S27: 7 | T27: Return from Bellville Campus | U27: Bellville Campus to Karl Bremmer hospital and return | V27: =COUNTIF(Bridge_Trip_Site!$A$2:$A$2000,A27) -> 1 | W27: 780 | X27: =IF(AND(ISNUMBER(M27),ISNUMBER(W27)),M27*W27,"") -> 14040 | Y27: 28 | Z27: Quoted (TSQT)
A28: T2024-027 | B28: AY2024 | C28: Request (AY2024) | D28: 3 | E28: =INDEX(Dim_Department!$B$2:$B$5,MATCH(D28,Dim_Department!$A$2:$A$5,0)) -> MITS | F28: V02 | G28: TSQT0003107 | H28: Stated | I28: 45418 | J28: 45455 | K28: 06, 07, 09, 13, 14, 16 May & 09, 10, 12 June 2024 | L28: 9 | M28: 9 | N28: Matches units (9) | O28: 0.75 | P28: 0.29166667 | Q28: Night duty | R28: 18h00 return 07h00 | S28: 7 | T28: Return from Bellville Campus | U28: Bellville Campus to Tygerberg hospital and return | V28: =COUNTIF(Bridge_Trip_Site!$A$2:$A$2000,A28) -> 1 | W28: 780 | X28: =IF(AND(ISNUMBER(M28),ISNUMBER(W28)),M28*W28,"") -> 7020 | Y28: 29 | Z28: Quoted (TSQT)
A29: T2024-028 | B29: AY2024 | C29: Request (AY2024) | D29: 3 | E29: =INDEX(Dim_Department!$B$2:$B$5,MATCH(D29,Dim_Department!$A$2:$A$5,0)) -> MITS | F29: V02 | G29: TSQT0003107 | H29: Stated | I29: 45423 | J29: 45460 | K29: 11, 18, 19 May & 15, 17 June 2024 | L29: 5 | M29: 5 | N29: Matches units (5) | O29: 0.29166667 | P29: 0.66666667 | Q29: Day | R29: 07h00 return 16h00 | S29: 7 | T29: Return from Bellville Campus | U29: Bellville Campus to Tygerberg hospital and retur | V29: =COUNTIF(Bridge_Trip_Site!$A$2:$A$2000,A29) -> 1 | W29: 780 | X29: =IF(AND(ISNUMBER(M29),ISNUMBER(W29)),M29*W29,"") -> 3900 | Y29: 30 | Z29: Quoted (TSQT)
A30: T2024-029 | B30: AY2024 | C30: Request (AY2024) | D30: 3 | E30: =INDEX(Dim_Department!$B$2:$B$5,MATCH(D30,Dim_Department!$A$2:$A$5,0)) -> MITS | F30: V02 | G30: TSQT0003107 | H30: Stated | I30: 45425 | J30: 45429 | K30: 13, 14, 15, 16, 17 May 2024 | L30: 5 | M30: 5 | N30: Matches units (5) | O30: 0.25 | P30: 0.66666667 | Q30: Day | R30: 06h00 return 16h00 | S30: 7 | T30: Return from Bellville Campus | U30: Bellville Campus to Mowbray & Red Cross hospitals and return | V30: =COUNTIF(Bridge_Trip_Site!$A$2:$A$2000,A30) -> 2 | W30: 980 | X30: =IF(AND(ISNUMBER(M30),ISNUMBER(W30)),M30*W30,"") -> 4900 | Y30: 31 | Z30: Quoted (TSQT)
A31: T2024-030 | B31: AY2024 | C31: Request (AY2024) | D31: 3 | E31: =INDEX(Dim_Department!$B$2:$B$5,MATCH(D31,Dim_Department!$A$2:$A$5,0)) -> MITS | F31: V02 | G31: TSQT0003107 | H31: Stated | I31: 45425 | J31: 45464 | K31: 13, 14, 15, 16, 17 May & 18, 19, 20, 21 June 2024 | L31: 9 | M31: 9 | N31: Matches units (9) | O31: 0.27083333 | P31: 0.66666667 | Q31: Day | R31: 06h30 return 16h00 | S31: 7 | T31: Return from Bellville Campus | U31: Bellville Campus to Tygerberg hospital and return | V31: =COUNTIF(Bridge_Trip_Site!$A$2:$A$2000,A31) -> 1 | W31: 980 | X31: =IF(AND(ISNUMBER(M31),ISNUMBER(W31)),M31*W31,"") -> 8820 | Y31: 32 | Z31: Quoted (TSQT)
A32: T2024-031 | B32: AY2024 | C32: Request (AY2024) | D32: 1 | E32: =INDEX(Dim_Department!$B$2:$B$5,MATCH(D32,Dim_Department!$A$2:$A$5,0)) -> Nursing | F32: V04 | G32: TSQT0003190 | H32: Stated | I32: 45453 | J32: 45471 | K32: 10-28 June 2024 | L32: 14 | M32: 14 | N32: Matches units (14) | O32: 0.22916667 | P32: 0.6875 | Q32: Day | R32: 05h30 return 16h30 | S32: 13 | T32: Return from Bellville Campus | U32: Bellville Campus to Pinelands CPOA, Manor Care CPOA, Sea Point CPOA and return | V32: =COUNTIF(Bridge_Trip_Site!$A$2:$A$2000,A32) -> 3 | W32: 1400 | X32: =IF(AND(ISNUMBER(M32),ISNUMBER(W32)),M32*W32,"") -> 19600 | Y32: 33 | Z32: Quoted (TSQT)
... A42: T2024-041 | B42: AY2024 | C42: Request (AY2024) | D42: 1 | E42: =INDEX(Dim_Department!$B$2:$B$5,MATCH(D42,Dim_Department!$A$2:$A$5,0)) -> Nursing | F42: V04 | G42: TSQT0003201 | H42: Stated | I42: 45461 | J42: 45471 | K42: 18-28 June 2024 | L42: 9 | M42: 9 | N42: Matches units (9) | O42: 0.72916667 | P42: 0.3125 | Q42: Night duty | R42: 17h30 return 07h30 | S42: 13 | T42: Return from Bellville Campus | U42: Bellville Campus to Stellenbosch hospital and return TRIP | V42: =COUNTIF(Bridge_Trip_Site!$A$2:$A$2000,A42) -> 1 | W42: 2600 | X42: =IF(AND(ISNUMBER(M42),ISNUMBER(W42)),M42*W42,"") -> 23400 | Y42: 43 | Z42: Quoted (TSQT)
A43: T2024-042 | B43: AY2024 | C43: Request (AY2024) | D43: 1 | E43: =INDEX(Dim_Department!$B$2:$B$5,MATCH(D43,Dim_Department!$A$2:$A$5,0)) -> Nursing | F43: V06 | G43: TSQT0003201 | H43: Stated | I43: 45445 | J43: 45457 | K43: 02 June 2024 return 14 June 2024 | L43: 2 | M43: 2 | N43: Matches units (2) | Q43: Not specified | R43: none specified | S43: 19 | T43: Return from Bellville Campus | U43: Bellville Campus to CPT Airport and return 14 June 2024 back to campus TRIP | V43: =COUNTIF(Bridge_Trip_Site!$A$2:$A$2000,A43) -> 1 | W43: 2450 | X43: =IF(AND(ISNUMBER(M43),ISNUMBER(W43)),M43*W43,"") -> 4900 | Y43: 44 | Z43: Quoted (TSQT)
A44: T2024-043 | B44: AY2024 | C44: Request (AY2024) | D44: 3 | E44: =INDEX(Dim_Department!$B$2:$B$5,MATCH(D44,Dim_Department!$A$2:$A$5,0)) -> MITS | F44: V02 | G44: TSQT0003285 | H44: Stated | I44: 45488 | J44: 45568 | K44: 15-19, 22-26, 29, 30, 31 July; 01, 02, 05-08, 12-16, 19-23 August; 25-27, 30 September; 01-03 October 2024 | L44: 36 | M44: 30 | N44: MISMATCH: 36 dates parsed vs 30 units booked | O44: 0.25 | P44: 0.66666667 | Q44: Day | R44: 06h00 return 16h00 | S44: 7 | T44: Return from Bellville Campus | U44: Bellville Campus to Red Cross hospital and return | V44: =COUNTIF(Bridge_Trip_Site!$A$2:$A$2000,A44) -> 1 | W44: 850 | X44: =IF(AND(ISNUMBER(M44),ISNUMBER(W44)),M44*W44,"") -> 25500 | Y44: 45 | Z44: Quoted (TSQT)
A45: T2024-044 | B45: AY2024 | C45: Request (AY2024) | D45: 3 | E45: =INDEX(Dim_Department!$B$2:$B$5,MATCH(D45,Dim_Department!$A$2:$A$5,0)) -> MITS | F45: V02 | G45: TSQT0003285 | H45: Stated | I45: 45488 | J45: 45568 | K45: 15-19, 22-26 July 16, 19-23 August; 16-20, 30 September, 01-03 October 2024 | L45: 25 | M45: 29 | N45: MISMATCH: 25 dates parsed vs 29 units booked | O45: 0.27083333 | P45: 0.66666667 | Q45: Day | R45: 6h30 return 16h00 | S45: 7 | T45: Return from Bellville Campus | U45: Bellville Campus to Khayelitsha District hospital and return | V45: =COUNTIF(Bridge_Trip_Site!$A$2:$A$2000,A45) -> 1 | W45: 850 | X45: =IF(AND(ISNUMBER(M45),ISNUMBER(W45)),M45*W45,"") -> 24650 | Y45: 46 | Z45: Quoted (TSQT)
A46: T2024-045 | B46: AY2024 | C46: Request (AY2024) | D46: 3 | E46: =INDEX(Dim_Department!$B$2:$B$5,MATCH(D46,Dim_Department!$A$2:$A$5,0)) -> MITS | F46: V02 | G46: TSQT0003285 | H46: Stated | I46: 45495 | J46: 45562 | K46: 22-26 July; 12-16, 19- 23 August; 16-20, 25-27 September | L46: 23 | M46: 23 | N46: Matches units (23) | O46: 0.27083333 | P46: 0.66666667 | Q46: Day | R46: 6h30 return 16h00 | S46: 7 | T46: Return from Bellville Campus | U46: Bellville Campus to Karl Bremmer hospital and return | V46: =COUNTIF(Bridge_Trip_Site!$A$2:$A$2000,A46) -> 1 | W46: 780 | X46: =IF(AND(ISNUMBER(M46),ISNUMBER(W46)),M46*W46,"") -> 17940 | Y46: 47 | Z46: Quoted (TSQT)
A47: T2024-046 | B47: AY2024 | C47: Request (AY2024) | D47: 3 | E47: =INDEX(Dim_Department!$B$2:$B$5,MATCH(D47,Dim_Department!$A$2:$A$5,0)) -> MITS | F47: V02 | G47: TSQT0003285 | H47: Stated | I47: 45488 | J47: 45554 | K47: 15, 16, 18, 22, 23, 25 July; 16, 17, 19 September 2024 | L47: 9 | M47: 9 | N47: Matches units (9) | O47: 0.75 | P47: 0.29166667 | Q47: Night duty | R47: 18h00 return 07h00 | S47: 7 | T47: Return from Bellville Campus | U47: Bellville campus to GSH and return | V47: =COUNTIF(Bridge_Trip_Site!$A$2:$A$2000,A47) -> 1 | W47: 850 | X47: =IF(AND(ISNUMBER(M47),ISNUMBER(W47)),M47*W47,"") -> 7650 | Y47: 48 | Z47: Quoted (TSQT)
A48: T2024-047 | B48: AY2024 | C48: Request (AY2024) | D48: 3 | E48: =INDEX(Dim_Department!$B$2:$B$5,MATCH(D48,Dim_Department!$A$2:$A$5,0)) -> MITS | F48: V02 | G48: TSQT0003285 | H48: Stated | I48: 45493 | J48: 45556 | K48: 20 July; 10, 18, 24, 31 August; 21 September 2024 | L48: 6 | M48: 6 | N48: Matches units (6) | O48: 0.29166667 | P48: 0.66666667 | Q48: Day | R48: 07h00 return 16h00 | S48: 7 | T48: Return from Bellville Campus | U48: Bellville campus to GSH and return | V48: =COUNTIF(Bridge_Trip_Site!$A$2:$A$2000,A48) -> 1 | W48: 850 | X48: =IF(AND(ISNUMBER(M48),ISNUMBER(W48)),M48*W48,"") -> 5100 | Y48: 49 | Z48: Quoted (TSQT)
A49: T2024-048 | B49: AY2024 | C49: Request (AY2024) | D49: 3 | E49: =INDEX(Dim_Department!$B$2:$B$5,MATCH(D49,Dim_Department!$A$2:$A$5,0)) -> MITS | F49: V02 | G49: TSQT0003285 | H49: Stated | I49: 45501 | J49: 45567 | K49: 28, 29, 31 July; 19, 20, 22, 25, 26, 28 August; 01, 02, 04, 16, 17, 19, 23 ,24, 26, 29, 30 September; 02 October 2024- | L49: 21 | M49: 21 | N49: Matches units (21) | O49: 0.75 | P49: 0.29166667 | Q49: Night duty | R49: 18h00 return 07h00 | S49: 7 | T49: Return from Bellville Campus | U49: Bvl to TBH and return | V49: =COUNTIF(Bridge_Trip_Site!$A$2:$A$2000,A49) -> 1 | W49: 780 | X49: =IF(AND(ISNUMBER(M49),ISNUMBER(W49)),M49*W49,"") -> 16380 | Y49: 50 | Z49: Quoted (TSQT)
...

Sheet Bridge_Trip_Site
A1: Trip_ID | B1: Site_ID | C1: Site_Name
A2: T2024-001 | B2: S105 | C2: =INDEX(Dim_Site!$B$2:$B$106,MATCH(B2,Dim_Site!$A$2:$A$106,0)) -> Worcester Hospital
A3: T2024-002 | B3: S105 | C3: =INDEX(Dim_Site!$B$2:$B$106,MATCH(B3,Dim_Site!$A$2:$A$106,0)) -> Worcester Hospital
A4: T2024-003 | B4: S100 | C4: =INDEX(Dim_Site!$B$2:$B$106,MATCH(B4,Dim_Site!$A$2:$A$106,0)) -> Tygerberg Hospital
A5: T2024-003 | B5: S034 | C5: =INDEX(Dim_Site!$B$2:$B$106,MATCH(B5,Dim_Site!$A$2:$A$106,0)) -> Karl Bremer Hospital
A6: T2024-004 | B6: S067 | C6: =INDEX(Dim_Site!$B$2:$B$106,MATCH(B6,Dim_Site!$A$2:$A$106,0)) -> New Somerset Hospital
A7: T2024-005 | B7: S061 | C7: =INDEX(Dim_Site!$B$2:$B$106,MATCH(B7,Dim_Site!$A$2:$A$106,0)) -> Mitchells Plain (facility not stated)
A8: T2024-005 | B8: S058 | C8: =INDEX(Dim_Site!$B$2:$B$106,MATCH(B8,Dim_Site!$A$2:$A$106,0)) -> Michael Mapongwana CDC
A9: T2024-005 | B9: S089 | C9: =INDEX(Dim_Site!$B$2:$B$106,MATCH(B9,Dim_Site!$A$2:$A$106,0)) -> Site B, Khayelitsha CDC
A10: T2024-005 | B10: S044 | C10: =INDEX(Dim_Site!$B$2:$B$106,MATCH(B10,Dim_Site!$A$2:$A$106,0)) -> Kuyasa Clinic (Khayelitsha)
A11: T2024-005 | B11: S068 | C11: =INDEX(Dim_Site!$B$2:$B$106,MATCH(B11,Dim_Site!$A$2:$A$106,0)) -> Nolungile CDC
A12: T2024-005 | B12: S084 | C12: =INDEX(Dim_Site!$B$2:$B$106,MATCH(B12,Dim_Site!$A$2:$A$106,0)) -> Rocklands Clinic
A13: T2024-005 | B13: S050 | C13: =INDEX(Dim_Site!$B$2:$B$106,MATCH(B13,Dim_Site!$A$2:$A$106,0)) -> Lentegeur Clinic
... A314: P2025-096 | B314: S104 | C314: =INDEX(Dim_Site!$B$2:$B$106,MATCH(B314,Dim_Site!$A$2:$A$106,0)) -> Western Cape Rehabilitation Centre

Sheet Bridge_Trip_Date
A1: Trip_ID | B1: Date | C1: Reconciled_To_Units
A2: T2024-001 | B2: 45383 | C2: Yes
A3: T2024-002 | B3: 45423 | C3: Yes
A4: T2024-003 | B4: 45384 | C4: Yes
A5: T2024-003 | B5: 45385 | C5: Yes
A6: T2024-003 | B6: 45386 | C6: Yes
A7: T2024-003 | B7: 45387 | C7: Yes
A8: T2024-003 | B8: 45390 | C8: Yes
A9: T2024-003 | B9: 45391 | C9: Yes
A10: T2024-003 | B10: 45392 | C10: Yes
A11: T2024-003 | B11: 45393 | C11: Yes
A12: T2024-003 | B12: 45394 | C12: Yes
A13: T2024-004 | B13: 45384 | C13: Yes
... A1247: T2024-092 | B1247: 45436 | C1247: No

Sheet Dim_Site
A1: Site_ID | B1: Site_Name | C1: Locality | D1: Site_Type | E1: Tier | F1: Name_Status | G1: Lines_AY2024 | H1: Lines_AY2025
A2: S001 | B2: Alexandra Hospital | C2: Alexandra | D2: Hospital | E2: Not classified | F2: Name as in AY2025 document | G2: =COUNTIFS(Bridge_Trip_Site!$B$2:$B$2000,A2,Bridge_Trip_Site!$A$2:$A$2000,"T2024-*") -> 0 | H2: =COUNTIFS(Bridge_Trip_Site!$B$2:$B$2000,A2,Bridge_Trip_Site!$A$2:$A$2000,"P2025-*") -> 1
A3: S002 | B3: Anchusa CPOA | C3: Anchusa | D3: CPOA | E3: Not classified | F3: Name as in AY2025 document | G3: =COUNTIFS(Bridge_Trip_Site!$B$2:$B$2000,A3,Bridge_Trip_Site!$A$2:$A$2000,"T2024-*") -> 2 | H3: =COUNTIFS(Bridge_Trip_Site!$B$2:$B$2000,A3,Bridge_Trip_Site!$A$2:$A$2000,"P2025-*") -> 1
A4: S003 | B4: Avondrust CPOA | C4: Avondrust | D4: CPOA | E4: Not classified | F4: Name as in AY2025 document | G4: =COUNTIFS(Bridge_Trip_Site!$B$2:$B$2000,A4,Bridge_Trip_Site!$A$2:$A$2000,"T2024-*") -> 2 | H4: =COUNTIFS(Bridge_Trip_Site!$B$2:$B$2000,A4,Bridge_Trip_Site!$A$2:$A$2000,"P2025-*") -> 1
A5: S004 | B5: Bishop Lavis CDC | C5: Bishop Lavis | D5: CDC | E5: Not classified | F5: Name as in AY2025 document | G5: =COUNTIFS(Bridge_Trip_Site!$B$2:$B$2000,A5,Bridge_Trip_Site!$A$2:$A$2000,"T2024-*") -> 0 | H5: =COUNTIFS(Bridge_Trip_Site!$B$2:$B$2000,A5,Bridge_Trip_Site!$A$2:$A$2000,"P2025-*") -> 1
A6: S005 | B6: Constantia Place CPOA | C6: Constantia Place | D6: CPOA | E6: Not classified | F6: Name as in AY2025 document | G6: =COUNTIFS(Bridge_Trip_Site!$B$2:$B$2000,A6,Bridge_Trip_Site!$A$2:$A$2000,"T2024-*") -> 0 | H6: =COUNTIFS(Bridge_Trip_Site!$B$2:$B$2000,A6,Bridge_Trip_Site!$A$2:$A$2000,"P2025-*") -> 1
A7: S006 | B7: CPT International Airport | C7: CPT International Airport | D7: Other (non-clinical) | E7: Not classified | F7: AY2024 name only | G7: =COUNTIFS(Bridge_Trip_Site!$B$2:$B$2000,A7,Bridge_Trip_Site!$A$2:$A$2000,"T2024-*") -> 2 | H7: =COUNTIFS(Bridge_Trip_Site!$B$2:$B$2000,A7,Bridge_Trip_Site!$A$2:$A$2000,"P2025-*") -> 0
A8: S007 | B8: Delft CDC | C8: Delft | D8: CDC | E8: Not classified | F8: Name as in AY2025 document | G8: =COUNTIFS(Bridge_Trip_Site!$B$2:$B$2000,A8,Bridge_Trip_Site!$A$2:$A$2000,"T2024-*") -> 0 | H8: =COUNTIFS(Bridge_Trip_Site!$B$2:$B$2000,A8,Bridge_Trip_Site!$A$2:$A$2000,"P2025-*") -> 1
A9: S008 | B9: Delft CHC | C9: Delft | D9: CHC | E9: Not classified | F9: Name as in AY2025 document | G9: =COUNTIFS(Bridge_Trip_Site!$B$2:$B$2000,A9,Bridge_Trip_Site!$A$2:$A$2000,"T2024-*") -> 0 | H9: =COUNTIFS(Bridge_Trip_Site!$B$2:$B$2000,A9,Bridge_Trip_Site!$A$2:$A$2000,"P2025-*") -> 1
A10: S009 | B10: Dirkie Uys (Goodwood) CDC | C10: Dirkie Uys | D10: CDC | E10: Not classified | F10: Name as in AY2025 document | G10: =COUNTIFS(Bridge_Trip_Site!$B$2:$B$2000,A10,Bridge_Trip_Site!$A$2:$A$2000,"T2024-*") -> 1 | H10: =COUNTIFS(Bridge_Trip_Site!$B$2:$B$2000,A10,Bridge_Trip_Site!$A$2:$A$2000,"P2025-*") -> 1
A11: S010 | B11: District 6 CDC | C11: District 6 | D11: CDC | E11: Not classified | F11: Name as in AY2025 document | G11: =COUNTIFS(Bridge_Trip_Site!$B$2:$B$2000,A11,Bridge_Trip_Site!$A$2:$A$2000,"T2024-*") -> 0 | H11: =COUNTIFS(Bridge_Trip_Site!$B$2:$B$2000,A11,Bridge_Trip_Site!$A$2:$A$2000,"P2025-*") -> 1
A12: S011 | B12: District 6 CHC | C12: District 6 | D12: CHC | E12: Not classified | F12: AY2024 name only | G12: =COUNTIFS(Bridge_Trip_Site!$B$2:$B$2000,A12,Bridge_Trip_Site!$A$2:$A$2000,"T2024-*") -> 1 | H12: =COUNTIFS(Bridge_Trip_Site!$B$2:$B$2000,A12,Bridge_Trip_Site!$A$2:$A$2000,"P2025-*") -> 0
A13: S012 | B13: District 6 Clinic | C13: District 6 | D13: Clinic | E13: Not classified | F13: AY2024 name only | G13: =COUNTIFS(Bridge_Trip_Site!$B$2:$B$2000,A13,Bridge_Trip_Site!$A$2:$A$2000,"T2024-*") -> 1 | H13: =COUNTIFS(Bridge_Trip_Site!$B$2:$B$2000,A13,Bridge_Trip_Site!$A$2:$A$2000,"P2025-*") -> 0
... A106: S105 | B106: Worcester Hospital | C106: Worcester | D106: Hospital | E106: Not classified | F106: AY2024 name only | G106: =COUNTIFS(Bridge_Trip_Site!$B$2:$B$2000,A106,Bridge_Trip_Site!$A$2:$A$2000,"T2024-*") -> 3 | H106: =COUNTIFS(Bridge_Trip_Site!$B$2:$B$2000,A106,Bridge_Trip_Site!$A$2:$A$2000,"P2025-*") -> 0

Sheet Dim_Department
A1: Dept_ID | B1: Dept_Code | C1: Department_Name | D1: Names_In_Source | E1: Registered_Students_AY2025 | F1: Students_Note | G1: Faculty_Funded_Transport
A2: 1 | B2: Nursing | C2: Nursing Science | D2: NURSING / Nursing | E2: 240 | F2: Undergrad: 60 x 4 = 240 (AY2025 document) | G2: Yes (not stated otherwise)
A3: 2 | B3: DEMS | C3: Emergency Medical Sciences | D3: DEMS (AY2024) / EMS (AY2025) | E3: 290 | F3: AY2025 document | G3: Yes (not stated otherwise)
A4: 3 | B4: MITS | C4: Medical Imaging and Therapeutic Sciences | D4: MITS | E4: 409 | F4: AY2025 document: not all registered students use CPUT transport | G4: Yes (not stated otherwise)
A5: 4 | B5: Biomed | C5: Biomed (full name not stated in source) | D5: Biomed | E5: 101 | F5: AY2025 document | G5: No faculty-funded transport (AY2025 document)

Sheet Dim_Vehicle
A1: Vehicle_ID | B1: Vehicle_Label | C1: Capacity | D1: Basis
A2: V01 | B2: 4-seater | C2: 4 | D2: AY2024: value in 'number of students' column read as capacity (to confirm)
A3: V02 | B3: 7-seater | C3: 7 | D3: AY2024: value in 'number of students' column read as capacity (to confirm)
A4: V03 | B4: 10-seater | C4: 10 | D4: AY2024: value in 'number of students' column read as capacity (to confirm)
A5: V04 | B5: 13-seater | C5: 13 | D5: AY2024: value in 'number of students' column read as capacity (to confirm)
A6: V05 | B6: 18-seater | C6: 18 | D6: AY2024: value in 'number of students' column read as capacity (to confirm)
A7: V06 | B7: 19-seater | C7: 19 | D7: AY2024: value in 'number of students' column read as capacity (to confirm)
A8: V07 | B8: 22-seater | C8: 22 | D8: AY2024: value in 'number of students' column read as capacity (to confirm)
A9: V08 | B9: 60-seater | C9: 60 | D9: AY2024: value in 'number of students' column read as capacity (to confirm)
A10: V09 | B10: Mixed 7 / 13-seater (not specified per site) | D10: AY2025 Nursing: document says mostly 7-seaters, also 13-seaters

Sheet Dim_Date
A1: Date | B1: Year | C1: Month_No | D1: Month | E1: Quarter | F1: Weekday | G1: Is_Weekend | H1: Public_Holiday
A2: 45292 | B2: =YEAR(A2) -> 2024 | C2: =MONTH(A2) -> 1 | D2: =TEXT(A2,"mmm") -> Jan | E2: ="Q"&ROUNDUP(C2/3,0) -> Q1 | F2: =TEXT(A2,"ddd") -> Mon | G2: =IF(WEEKDAY(A2,2)>5,"Yes","No") -> No | H2: New Year's Day
A3: 45293 | B3: =YEAR(A3) -> 2024 | C3: =MONTH(A3) -> 1 | D3: =TEXT(A3,"mmm") -> Jan | E3: ="Q"&ROUNDUP(C3/3,0) -> Q1 | F3: =TEXT(A3,"ddd") -> Tue | G3: =IF(WEEKDAY(A3,2)>5,"Yes","No") -> No
A4: 45294 | B4: =YEAR(A4) -> 2024 | C4: =MONTH(A4) -> 1 | D4: =TEXT(A4,"mmm") -> Jan | E4: ="Q"&ROUNDUP(C4/3,0) -> Q1 | F4: =TEXT(A4,"ddd") -> Wed | G4: =IF(WEEKDAY(A4,2)>5,"Yes","No") -> No
A5: 45295 | B5: =YEAR(A5) -> 2024 | C5: =MONTH(A5) -> 1 | D5: =TEXT(A5,"mmm") -> Jan | E5: ="Q"&ROUNDUP(C5/3,0) -> Q1 | F5: =TEXT(A5,"ddd") -> Thu | G5: =IF(WEEKDAY(A5,2)>5,"Yes","No") -> No
A6: 45296 | B6: =YEAR(A6) -> 2024 | C6: =MONTH(A6) -> 1 | D6: =TEXT(A6,"mmm") -> Jan | E6: ="Q"&ROUNDUP(C6/3,0) -> Q1 | F6: =TEXT(A6,"ddd") -> Fri | G6: =IF(WEEKDAY(A6,2)>5,"Yes","No") -> No
A7: 45297 | B7: =YEAR(A7) -> 2024 | C7: =MONTH(A7) -> 1 | D7: =TEXT(A7,"mmm") -> Jan | E7: ="Q"&ROUNDUP(C7/3,0) -> Q1 | F7: =TEXT(A7,"ddd") -> Sat | G7: =IF(WEEKDAY(A7,2)>5,"Yes","No") -> Yes
A8: 45298 | B8: =YEAR(A8) -> 2024 | C8: =MONTH(A8) -> 1 | D8: =TEXT(A8,"mmm") -> Jan | E8: ="Q"&ROUNDUP(C8/3,0) -> Q1 | F8: =TEXT(A8,"ddd") -> Sun | G8: =IF(WEEKDAY(A8,2)>5,"Yes","No") -> Yes
A9: 45299 | B9: =YEAR(A9) -> 2024 | C9: =MONTH(A9) -> 1 | D9: =TEXT(A9,"mmm") -> Jan | E9: ="Q"&ROUNDUP(C9/3,0) -> Q1 | F9: =TEXT(A9,"ddd") -> Mon | G9: =IF(WEEKDAY(A9,2)>5,"Yes","No") -> No
A10: 45300 | B10: =YEAR(A10) -> 2024 | C10: =MONTH(A10) -> 1 | D10: =TEXT(A10,"mmm") -> Jan | E10: ="Q"&ROUNDUP(C10/3,0) -> Q1 | F10: =TEXT(A10,"ddd") -> Tue | G10: =IF(WEEKDAY(A10,2)>5,"Yes","No") -> No
A11: 45301 | B11: =YEAR(A11) -> 2024 | C11: =MONTH(A11) -> 1 | D11: =TEXT(A11,"mmm") -> Jan | E11: ="Q"&ROUNDUP(C11/3,0) -> Q1 | F11: =TEXT(A11,"ddd") -> Wed | G11: =IF(WEEKDAY(A11,2)>5,"Yes","No") -> No
A12: 45302 | B12: =YEAR(A12) -> 2024 | C12: =MONTH(A12) -> 1 | D12: =TEXT(A12,"mmm") -> Jan | E12: ="Q"&ROUNDUP(C12/3,0) -> Q1 | F12: =TEXT(A12,"ddd") -> Thu | G12: =IF(WEEKDAY(A12,2)>5,"Yes","No") -> No
A13: 45303 | B13: =YEAR(A13) -> 2024 | C13: =MONTH(A13) -> 1 | D13: =TEXT(A13,"mmm") -> Jan | E13: ="Q"&ROUNDUP(C13/3,0) -> Q1 | F13: =TEXT(A13,"ddd") -> Fri | G13: =IF(WEEKDAY(A13,2)>5,"Yes","No") -> No
A14: 45304 | B14: =YEAR(A14) -> 2024 | C14: =MONTH(A14) -> 1 | D14: =TEXT(A14,"mmm") -> Jan | E14: ="Q"&ROUNDUP(C14/3,0) -> Q1 | F14: =TEXT(A14,"ddd") -> Sat | G14: =IF(WEEKDAY(A14,2)>5,"Yes","No") -> Yes
... A81: 45371 | B81: =YEAR(A81) -> 2024 | C81: =MONTH(A81) -> 3 | D81: =TEXT(A81,"mmm") -> Mar | E81: ="Q"&ROUNDUP(C81/3,0) -> Q1 | F81: =TEXT(A81,"ddd") -> Wed | G81: =IF(WEEKDAY(A81,2)>5,"Yes","No") -> No
A82: 45372 | B82: =YEAR(A82) -> 2024 | C82: =MONTH(A82) -> 3 | D82: =TEXT(A82,"mmm") -> Mar | E82: ="Q"&ROUNDUP(C82/3,0) -> Q1 | F82: =TEXT(A82,"ddd") -> Thu | G82: =IF(WEEKDAY(A82,2)>5,"Yes","No") -> No | H82: Human Rights Day
A83: 45373 | B83: =YEAR(A83) -> 2024 | C83: =MONTH(A83) -> 3 | D83: =TEXT(A83,"mmm") -> Mar | E83: ="Q"&ROUNDUP(C83/3,0) -> Q1 | F83: =TEXT(A83,"ddd") -> Fri | G83: =IF(WEEKDAY(A83,2)>5,"Yes","No") -> No
A84: 45374 | B84: =YEAR(A84) -> 2024 | C84: =MONTH(A84) -> 3 | D84: =TEXT(A84,"mmm") -> Mar | E84: ="Q"&ROUNDUP(C84/3,0) -> Q1 | F84: =TEXT(A84,"ddd") -> Sat | G84: =IF(WEEKDAY(A84,2)>5,"Yes","No") -> Yes
A85: 45375 | B85: =YEAR(A85) -> 2024 | C85: =MONTH(A85) -> 3 | D85: =TEXT(A85,"mmm") -> Mar | E85: ="Q"&ROUNDUP(C85/3,0) -> Q1 | F85: =TEXT(A85,"ddd") -> Sun | G85: =IF(WEEKDAY(A85,2)>5,"Yes","No") -> Yes
A86: 45376 | B86: =YEAR(A86) -> 2024 | C86: =MONTH(A86) -> 3 | D86: =TEXT(A86,"mmm") -> Mar | E86: ="Q"&ROUNDUP(C86/3,0) -> Q1 | F86: =TEXT(A86,"ddd") -> Mon | G86: =IF(WEEKDAY(A86,2)>5,"Yes","No") -> No
A87: 45377 | B87: =YEAR(A87) -> 2024 | C87: =MONTH(A87) -> 3 | D87: =TEXT(A87,"mmm") -> Mar | E87: ="Q"&ROUNDUP(C87/3,0) -> Q1 | F87: =TEXT(A87,"ddd") -> Tue | G87: =IF(WEEKDAY(A87,2)>5,"Yes","No") -> No
A88: 45378 | B88: =YEAR(A88) -> 2024 | C88: =MONTH(A88) -> 3 | D88: =TEXT(A88,"mmm") -> Mar | E88: ="Q"&ROUNDUP(C88/3,0) -> Q1 | F88: =TEXT(A88,"ddd") -> Wed | G88: =IF(WEEKDAY(A88,2)>5,"Yes","No") -> No
A89: 45379 | B89: =YEAR(A89) -> 2024 | C89: =MONTH(A89) -> 3 | D89: =TEXT(A89,"mmm") -> Mar | E89: ="Q"&ROUNDUP(C89/3,0) -> Q1 | F89: =TEXT(A89,"ddd") -> Thu | G89: =IF(WEEKDAY(A89,2)>5,"Yes","No") -> No
A90: 45380 | B90: =YEAR(A90) -> 2024 | C90: =MONTH(A90) -> 3 | D90: =TEXT(A90,"mmm") -> Mar | E90: ="Q"&ROUNDUP(C90/3,0) -> Q1 | F90: =TEXT(A90,"ddd") -> Fri | G90: =IF(WEEKDAY(A90,2)>5,"Yes","No") -> No | H90: Good Friday
A91: 45381 | B91: =YEAR(A91) -> 2024 | C91: =MONTH(A91) -> 3 | D91: =TEXT(A91,"mmm") -> Mar | E91: ="Q"&ROUNDUP(C91/3,0) -> Q1 | F91: =TEXT(A91,"ddd") -> Sat | G91: =IF(WEEKDAY(A91,2)>5,"Yes","No") -> Yes
A92: 45382 | B92: =YEAR(A92) -> 2024 | C92: =MONTH(A92) -> 3 | D92: =TEXT(A92,"mmm") -> Mar | E92: ="Q"&ROUNDUP(C92/3,0) -> Q1 | F92: =TEXT(A92,"ddd") -> Sun | G92: =IF(WEEKDAY(A92,2)>5,"Yes","No") -> Yes
A93: 45383 | B93: =YEAR(A93) -> 2024 | C93: =MONTH(A93) -> 4 | D93: =TEXT(A93,"mmm") -> Apr | E93: ="Q"&ROUNDUP(C93/3,0) -> Q2 | F93: =TEXT(A93,"ddd") -> Mon | G93: =IF(WEEKDAY(A93,2)>5,"Yes","No") -> No | H93: Family Day
A94: 45384 | B94: =YEAR(A94) -> 2024 | C94: =MONTH(A94) -> 4 | D94: =TEXT(A94,"mmm") -> Apr | E94: ="Q"&ROUNDUP(C94/3,0) -> Q2 | F94: =TEXT(A94,"ddd") -> Tue | G94: =IF(WEEKDAY(A94,2)>5,"Yes","No") -> No
A95: 45385 | B95: =YEAR(A95) -> 2024 | C95: =MONTH(A95) -> 4 | D95: =TEXT(A95,"mmm") -> Apr | E95: ="Q"&ROUNDUP(C95/3,0) -> Q2 | F95: =TEXT(A95,"ddd") -> Wed | G95: =IF(WEEKDAY(A95,2)>5,"Yes","No") -> No
A96: 45386 | B96: =YEAR(A96) -> 2024 | C96: =MONTH(A96) -> 4 | D96: =TEXT(A96,"mmm") -> Apr | E96: ="Q"&ROUNDUP(C96/3,0) -> Q2 | F96: =TEXT(A96,"ddd") -> Thu | G96: =IF(WEEKDAY(A96,2)>5,"Yes","No") -> No
A97: 45387 | B97: =YEAR(A97) -> 2024 | C97: =MONTH(A97) -> 4 | D97: =TEXT(A97,"mmm") -> Apr | E97: ="Q"&ROUNDUP(C97/3,0) -> Q2 | F97: =TEXT(A97,"ddd") -> Fri | G97: =IF(WEEKDAY(A97,2)>5,"Yes","No") -> No
A98: 45388 | B98: =YEAR(A98) -> 2024 | C98: =MONTH(A98) -> 4 | D98: =TEXT(A98,"mmm") -> Apr | E98: ="Q"&ROUNDUP(C98/3,0) -> Q2 | F98: =TEXT(A98,"ddd") -> Sat | G98: =IF(WEEKDAY(A98,2)>5,"Yes","No") -> Yes
A99: 45389 | B99: =YEAR(A99) -> 2024 | C99: =MONTH(A99) -> 4 | D99: =TEXT(A99,"mmm") -> Apr | E99: ="Q"&ROUNDUP(C99/3,0) -> Q2 | F99: =TEXT(A99,"ddd") -> Sun | G99: =IF(WEEKDAY(A99,2)>5,"Yes","No") -> Yes
A100: 45390 | B100: =YEAR(A100) -> 2024 | C100: =MONTH(A100) -> 4 | D100: =TEXT(A100,"mmm") -> Apr | E100: ="Q"&ROUNDUP(C100/3,0) -> Q2 | F100: =TEXT(A100,"ddd") -> Mon | G100: =IF(WEEKDAY(A100,2)>5,"Yes","No") -> No
A101: 45391 | B101: =YEAR(A101) -> 2024 | C101: =MONTH(A101) -> 4 | D101: =TEXT(A101,"mmm") -> Apr | E101: ="Q"&ROUNDUP(C101/3,0) -> Q2 | F101: =TEXT(A101,"ddd") -> Tue | G101: =IF(WEEKDAY(A101,2)>5,"Yes","No") -> No
A102: 45392 | B102: =YEAR(A102) -> 2024 | C102: =MONTH(A102) -> 4 | D102: =TEXT(A102,"mmm") -> Apr | E102: ="Q"&ROUNDUP(C102/3,0) -> Q2 | F102: =TEXT(A102,"ddd") -> Wed | G102: =IF(WEEKDAY(A102,2)>5,"Yes","No") -> No
A103: 45393 | B103: =YEAR(A103) -> 2024 | C103: =MONTH(A103) -> 4 | D103: =TEXT(A103,"mmm") -> Apr | E103: ="Q"&ROUNDUP(C103/3,0) -> Q2 | F103: =TEXT(A103,"ddd") -> Thu | G103: =IF(WEEKDAY(A103,2)>5,"Yes","No") -> No
A104: 45394 | B104: =YEAR(A104) -> 2024 | C104: =MONTH(A104) -> 4 | D104: =TEXT(A104,"mmm") -> Apr | E104: ="Q"&ROUNDUP(C104/3,0) -> Q2 | F104: =TEXT(A104,"ddd") -> Fri | G104: =IF(WEEKDAY(A104,2)>5,"Yes","No") -> No
A105: 45395 | B105: =YEAR(A105) -> 2024 | C105: =MONTH(A105) -> 4 | D105: =TEXT(A105,"mmm") -> Apr | E105: ="Q"&ROUNDUP(C105/3,0) -> Q2 | F105: =TEXT(A105,"ddd") -> Sat | G105: =IF(WEEKDAY(A105,2)>5,"Yes","No") -> Yes
... A118: 45408 | B118: =YEAR(A118) -> 2024 | C118: =MONTH(A118) -> 4 | D118: =TEXT(A118,"mmm") -> Apr | E118: ="Q"&ROUNDUP(C118/3,0) -> Q2 | F118: =TEXT(A118,"ddd") -> Fri | G118: =IF(WEEKDAY(A118,2)>5,"Yes","No") -> No
...

Sheet Data Issues
A1: Issue_ID | B1: Severity | C1: Source | D1: Records affected | E1: Field | F1: Issue | G1: Treatment in this workbook | H1: Action needed
A2: DI-01 | B2: Medium | C2: AY2024 requests | D2: 54 rows (TSQT0002828, TSQT0002974, TSQT0002977, TSQT0003200, TSQT0003201, TSQT0003285, TSQT0003287, TSQT0003294, TSQT0003295, TSQT0003296, TSQT0003297, TSQT0003336) | E2: cost per unit / units | F2: Cost per unit and units are in each other's columns on 54 rows (e.g. units 30 and cost 850). | G2: Smaller value treated as units, larger as cost per unit. Every row's units x cost equals the stated total (checked). | H2: Confirm with the TSQT quotes; fix at source going forward.
A3: DI-02 | B3: Medium | C3: AY2024 requests | D3: 29 rows | E3: TSQT number | F3: TSQT number is blank on continuation rows. | G3: Filled down from the row above (TSQT_Source = 'Filled down...'). A few blocks have no TSQT of their own on the first row (e.g. rows below TSQT0003296/5/4), so the fill may attach a row to the wrong TSQT. | H3: Check blank-TSQT rows against the quotes.
A4: DI-03 | B4: Low | C4: AY2024 requests | D4: 82 rows | E4: Academic department | F4: Department only stated on the first row of each block; spelled NURSING / Nursing, DEMS (AY2025 document says EMS). | G4: Filled down; codes standardised to Nursing, DEMS, MITS. | H4: Agree one department code list with FHWS.
A5: DI-04 | B5: High | C5: AY2024 requests | D5: 14 lines: T2024-010, T2024-021, T2024-034, T2024-035, T2024-036, T2024-037, T2024-043, T2024-044, T2024-068, T2024-069, T2024-070, T2024-071, T2024-072, T2024-092 | E5: Date / units | F5: Number of dates parsed from the date text differs from units booked (long ranges where only some days were used, typos such as a missing '&', or units that do not match the dates). | G5: Start_Date/End_Date and Parsed_Trip_Days come from the text; Trips uses units as booked. Bridge_Trip_Date rows for these lines are marked Reconciled = No. | H5: Confirm actual trip days for these lines before using date-level analysis.
A6: DI-05 | B6: Low | C6: AY2024 requests | D6: 11 lines | E6: Date | F6: Weekday ranges only reconcile to units if a public holiday inside the range was counted as a trip day (e.g. 25-29 March 2024 includes Good Friday; 20-31 May 2024 includes 29 May election day). | G6: Holiday counted only where that makes the dates match units. | H6: Confirm whether trips ran on those public holidays.
A7: DI-06 | B7: Medium | C7: AY2024 requests | D7: Whole sheet | E7: Date | F7: Date column mixes real Excel dates, Excel serial numbers (e.g. 45418) and free text, with typos ('June 202', 'May2024', line breaks inside the text). | G7: Parsed into Start_Date, End_Date and a trip-day list; original text kept in Dates_As_Captured. | H7: Use one date per row or a date list in future submissions.
A8: DI-07 | B8: High | C8: AY2024 requests | D8: 22 lines | E8: Version date | F8: File is dated 19 Aug 2024 but 22 lines run to September-October 2024 (DEMS and MITS). These were booked/planned when the file was saved. | G8: Kept as recorded. AY2024 totals are bookings, not confirmed completed trips. | H8: Get the final AY2024 submissions or invoices to confirm actuals.
A9: DI-08 | B9: Medium | C9: AY2024 requests | D9: number of students column | E9: Vehicle | F9: Column 'number of students' holds 4, 7, 10, 13, 18, 19, 22 and 60. The AY2025 document refers to 7- and 13-seater vehicles, which supports reading it as vehicle capacity. | G9: Read as vehicle capacity; stored in Students_As_Captured and linked to Dim_Vehicle. | H9: Confirm meaning with FHWS. Values 4, 10, 18, 19, 22 and 60 look like one-off or non-standard vehicles.
A10: DI-09 | B10: Medium | C10: AY2024 requests | D10: T2024-034/T2024-035 | E10: Whole row | F10: Rows with the same TSQT, dates, route, units and cost appear twice. | G10: Both kept (cost counted twice). | H10: Confirm whether this is a duplicate booking or a duplicate entry (cost impact shown by the pair).
A11: DI-10 | B11: Medium | C11: AY2024 requests | D11: Route text | E11: Site | F11: Facility names are inconsistent (Bremmer/Bremer, Worester, Eersteriver, MOU vs CDC vs CHC vs clinic) and many clinics are listed without a facility type. | G11: Standardised to the AY2025 document's names where the match is clear; otherwise the site is named '<Name> (facility not stated)'. Locality column groups MOU/CDC/CHC/clinic of the same area (not assumed to be the same building). | H11: Agree a facility master list with FHWS.
A12: DI-11 | B12: Low | C12: AY2024 requests | D12: DEMS: 'Gugulethu hospital' | E12: Site | F12: AY2024 DEMS route says Gugulethu hospital; the AY2025 document lists Gugulethu CHC for DEMS. | G12: Kept as Gugulethu Hospital (as stated). | H12: Confirm whether these are the same facility.
... A22: DI-21 | B22: High | C22: Assumption | D22: 96 AY2025 lines | E22: Cost per trip | F22: AY2025 has no quotes. Cost per trip was assumed: same department's AY2024 cost for the same site (shared across the sites of a multi-site AY2024 route), else 3,600 (README cell) for sites the department did not serve in AY2024. Counts: AY2024 multi-site route, cost shared across its sites (same department): 45; AY2024 single-site trip (same department): 22; Assumed (site not served by this department in AY2024): 29 | G22: Cost_Basis, Cost_Source_Trip_IDs and Cost_Note columns in Fact_Trips show the source for every AY2025 line. Trips are blank, so no AY2025 total is calculated. | H22: Replace with AY2025 TSQT quotes when available; decide whether same-locality sites (see Cost_Note) should use AY2024 costs.

Sheet Schedule Organiser
A1: FHWS student transport: schedule organiser (dummy template)
A2: Legend: yellow cells are for typing (Department, Site and Vehicle have drop-down lists); grey cells are formulas. Rows 5-7 are EXAMPLES: overwrite or delete them. Cost per trip is typed in from the TSQT quote (no rate card yet).
A4: Date | B4: Department | C4: Site | D4: Depart time | E4: Return time | F4: Vehicle | G4: Students | H4: Trips | I4: Cost per trip | J4: Total cost | K4: Week no. | L4: Consolidation flag
A5: 45726 | B5: DEMS | C5: Tygerberg Hospital | D5: 0.25 | E5: 0.75 | F5: 7-seater | G5: 7 | H5: 1 | I5: 850 | J5: =IF(AND(ISNUMBER(H5),ISNUMBER(I5)),H5*I5,"") -> 850 | K5: =IF(ISNUMBER(A5),WEEKNUM(A5,2),"") -> 11 | L5: =IF(OR(A5="",C5=""),"",IF(COUNTIFS($A$5:$A$64,A5,$C$5:$C$64,C5,$B$5:$B$64,"<>"&B5)>0,"Same site, same day, another department: consider combining","")) -> Same site, same day, another department: consider combining
A6: 45726 | B6: MITS | C6: Tygerberg Hospital | D6: 0.29166667 | E6: 0.66666667 | F6: 7-seater | G6: 7 | H6: 1 | I6: 780 | J6: =IF(AND(ISNUMBER(H6),ISNUMBER(I6)),H6*I6,"") -> 780 | K6: =IF(ISNUMBER(A6),WEEKNUM(A6,2),"") -> 11 | L6: =IF(OR(A6="",C6=""),"",IF(COUNTIFS($A$5:$A$64,A6,$C$5:$C$64,C6,$B$5:$B$64,"<>"&B6)>0,"Same site, same day, another department: consider combining","")) -> Same site, same day, another department: consider combining
A7: 45727 | B7: Nursing | C7: Karl Bremer Hospital | D7: 0.22916667 | E7: 0.8125 | F7: 13-seater | G7: 13 | H7: 1 | I7: 980 | J7: =IF(AND(ISNUMBER(H7),ISNUMBER(I7)),H7*I7,"") -> 980 | K7: =IF(ISNUMBER(A7),WEEKNUM(A7,2),"") -> 11 | L7: =IF(OR(A7="",C7=""),"",IF(COUNTIFS($A$5:$A$64,A7,$C$5:$C$64,C7,$B$5:$B$64,"<>"&B7)>0,"Same site, same day, another department: consider combining",""))
J8: =IF(AND(ISNUMBER(H8),ISNUMBER(I8)),H8*I8,"") | K8: =IF(ISNUMBER(A8),WEEKNUM(A8,2),"") | L8: =IF(OR(A8="",C8=""),"",IF(COUNTIFS($A$5:$A$64,A8,$C$5:$C$64,C8,$B$5:$B$64,"<>"&B8)>0,"Same site, same day, another department: consider combining",""))
J9: =IF(AND(ISNUMBER(H9),ISNUMBER(I9)),H9*I9,"") | K9: =IF(ISNUMBER(A9),WEEKNUM(A9,2),"") | L9: =IF(OR(A9="",C9=""),"",IF(COUNTIFS($A$5:$A$64,A9,$C$5:$C$64,C9,$B$5:$B$64,"<>"&B9)>0,"Same site, same day, another department: consider combining",""))
J10: =IF(AND(ISNUMBER(H10),ISNUMBER(I10)),H10*I10,"") | K10: =IF(ISNUMBER(A10),WEEKNUM(A10,2),"") | L10: =IF(OR(A10="",C10=""),"",IF(COUNTIFS($A$5:$A$64,A10,$C$5:$C$64,C10,$B$5:$B$64,"<>"&B10)>0,"Same site, same day, another department: consider combining",""))
J11: =IF(AND(ISNUMBER(H11),ISNUMBER(I11)),H11*I11,"") | K11: =IF(ISNUMBER(A11),WEEKNUM(A11,2),"") | L11: =IF(OR(A11="",C11=""),"",IF(COUNTIFS($A$5:$A$64,A11,$C$5:$C$64,C11,$B$5:$B$64,"<>"&B11)>0,"Same site, same day, another department: consider combining",""))
J12: =IF(AND(ISNUMBER(H12),ISNUMBER(I12)),H12*I12,"") | K12: =IF(ISNUMBER(A12),WEEKNUM(A12,2),"") | L12: =IF(OR(A12="",C12=""),"",IF(COUNTIFS($A$5:$A$64,A12,$C$5:$C$64,C12,$B$5:$B$64,"<>"&B12)>0,"Same site, same day, another department: consider combining",""))
J13: =IF(AND(ISNUMBER(H13),ISNUMBER(I13)),H13*I13,"") | K13: =IF(ISNUMBER(A13),WEEKNUM(A13,2),"") | L13: =IF(OR(A13="",C13=""),"",IF(COUNTIFS($A$5:$A$64,A13,$C$5:$C$64,C13,$B$5:$B$64,"<>"&B13)>0,"Same site, same day, another department: consider combining",""))
J14: =IF(AND(ISNUMBER(H14),ISNUMBER(I14)),H14*I14,"") | K14: =IF(ISNUMBER(A14),WEEKNUM(A14,2),"") | L14: =IF(OR(A14="",C14=""),"",IF(COUNTIFS($A$5:$A$64,A14,$C$5:$C$64,C14,$B$5:$B$64,"<>"&B14)>0,"Same site, same day, another department: consider combining",""))
J15: =IF(AND(ISNUMBER(H15),ISNUMBER(I15)),H15*I15,"") | K15: =IF(ISNUMBER(A15),WEEKNUM(A15,2),"") | L15: =IF(OR(A15="",C15=""),"",IF(COUNTIFS($A$5:$A$64,A15,$C$5:$C$64,C15,$B$5:$B$64,"<>"&B15)>0,"Same site, same day, another department: consider combining",""))
J16: =IF(AND(ISNUMBER(H16),ISNUMBER(I16)),H16*I16,"") | K16: =IF(ISNUMBER(A16),WEEKNUM(A16,2),"") | L16: =IF(OR(A16="",C16=""),"",IF(COUNTIFS($A$5:$A$64,A16,$C$5:$C$64,C16,$B$5:$B$64,"<>"&B16)>0,"Same site, same day, another department: consider combining",""))
J17: =IF(AND(ISNUMBER(H17),ISNUMBER(I17)),H17*I17,"") | K17: =IF(ISNUMBER(A17),WEEKNUM(A17,2),"") | L17: =IF(OR(A17="",C17=""),"",IF(COUNTIFS($A$5:$A$64,A17,$C$5:$C$64,C17,$B$5:$B$64,"<>"&B17)>0,"Same site, same day, another department: consider combining",""))
J18: =IF(AND(ISNUMBER(H18),ISNUMBER(I18)),H18*I18,"") | K18: =IF(ISNUMBER(A18),WEEKNUM(A18,2),"") | L18: =IF(OR(A18="",C18=""),"",IF(COUNTIFS($A$5:$A$64,A18,$C$5:$C$64,C18,$B$5:$B$64,"<>"&B18)>0,"Same site, same day, another department: consider combining",""))
J19: =IF(AND(ISNUMBER(H19),ISNUMBER(I19)),H19*I19,"") | K19: =IF(ISNUMBER(A19),WEEKNUM(A19,2),"") | L19: =IF(OR(A19="",C19=""),"",IF(COUNTIFS($A$5:$A$64,A19,$C$5:$C$64,C19,$B$5:$B$64,"<>"&B19)>0,"Same site, same day, another department: consider combining",""))
... J64: =IF(AND(ISNUMBER(H64),ISNUMBER(I64)),H64*I64,"") | K64: =IF(ISNUMBER(A64),WEEKNUM(A64,2),"") | L64: =IF(OR(A64="",C64=""),"",IF(COUNTIFS($A$5:$A$64,A64,$C$5:$C$64,C64,$B$5:$B$64,"<>"&B64)>0,"Same site, same day, another department: consider combining",""))
I66: Total | J66: =SUM(J5:J64) -> 2610
